Workbook
Name _16_Aug_2014: M.Menu!#REF!
Name _16_Aug_2014: M.Menu!#REF!
Name _16_Aug_2014: '[1]ISPS csv File Definition'!$L$13
Name _16_Aug_2014: M.Menu!#REF!
Name _16_Aug_2014: M.Menu!#REF!
Name a: [2]DATA!#REF!
Name a: [2]DATA!#REF!
Name a: [2]DATA!#REF!
Name a: [2]DATA!#REF!
Name a: [2]DATA!#REF!
Name a: [2]DATA!#REF!
Name aa: #REF!
Name aa: #REF!
Name aa: #REF!
Name aa: #REF!
Name aa: #REF!
Name aa: #REF!
Name aa: #REF!
Name aa: #REF!
Name ABMUSTERE: #REF!
Name ABMUSTERE: #REF!
Name ABMUSTERE: #REF!
Name ABMUSTERE: #REF!
Name ABMUSTERE: #REF!
Name ABMUSTERE: #REF!
Name ABMUSTERE: #REF!
Name ABMUSTERE: #REF!
Name Agent: '[3]SHIP PARTICULARS'!$D$9
Name Agent_Adress_1: '[3]SHIP PARTICULARS'!$D$10
Name Agent_Adress_2: '[3]SHIP PARTICULARS'!$D$11
Name Agent_Adress_3: '[3]SHIP PARTICULARS'!$D$12
Name Agents: #REF!
Name Agents: #REF!
Name Agents: #REF!
Name Agents: #REF!
Name Agents: #REF!
Name Agents: #REF!
Name Agents: #REF!
Name Agents: #REF!
Name ALLOT: #REF!
Name ALLOT: #REF!
Name ALLOT: #REF!
Name ALLOT: #REF!
Name ALLOT: #REF!
Name ALLOT: #REF!
Name ALLOT: #REF!
Name ALLOT: #REF!
Name ALLOT_: #REF!
Name ALLOT_: #REF!
Name ALLOT_: #REF!
Name ALLOT_: #REF!
Name ALLOT_: #REF!
Name ALLOT_: #REF!
Name ALLOT_: #REF!
Name ALLOT_: #REF!
Name ANDERE_: #REF!
Name ANDERE_: #REF!
Name ANDERE_: #REF!
Name ANDERE_: #REF!
Name ANDERE_: #REF!

Sheet M.Menu
A1: 0 | B1: IMO Port Clearance Documents
B2: VESSEL'S BASIC INFORMATION
B3: Vessel Name | E3: Energy Endurance | J3: IMO No. | L3: 9948695 | R3: Gross Tonnage | S3: 111089
B4: Call Sign | E4: V7A7282 | J4: Port Registry | L4: Majuro | R4: Net Tonnage | S4: 33327
B5: Vessel Type | E5: LNG/C | J5: Date Registry | L5: 45630 | R5: Classification | S5: Lloyd's Register
B6: Owner | E6: Markoni Navigation S.A. | J6: Official Registry No. | L6: 10699 | R6: Trading Area | S6: WORLDWIDE
B7: Operator | E7: Alpha Gas S.A. | J7: Year Build | L7: 2024 | R7: No. of Crew | S7: =COUNT('DataBase (IMO form)'!B8:B35) -> 28
B8: Charterers | E8: NFE Transport Partners LLC | J8: Nationality | L8: Marshall Islands | R8: No. of Passengers | S8: 0
J9: Suez Canal ID | L9: 6026048 | R9: Panama Canal SIN | S9: 6026048
B10: VOYAGE's Basic Details
B11: Last Port | E11: BARCARENA | J11: Arrival Port | L11: Sabine Pass | R11: Next Port | S11: BARCARENA
B12: Country | E12: BRAZIL | J12: Country | L12: U.S.A. | R12: Country | S12: BRAZIL
B13: Arrival Date | E13: 46081 | J13: Arrival Date | L13: 46106 | P13: 20/04 | R13: Present Voyage No. | S13: VOY16
B14: Departure Date | E14: 46084 | J14: Departure Date | R14: Departure Voyage No. | S14: VOY15
B15: Cargo Operation | E15: DISCHARGING | I15: Discharging | J15: Cargo Operation | L15: LOADING | R15: Name of Master | S15: CAPT. WENDT ROBERT
B16: Description of Cargo | E16: LNG | J16: Description of Cargo | L16: LNG | R16: Signature | S16: CAPT. WENDT ROBERT
B18: DOCUMENT/s Required on Arrival as per FairPlay/Agent
O20: Vessel's Agent
O21: Address
O22: Contact Details
S23: 360-734-5194 | T23: 360-734-5194 | U23: 360-734-5194
H26: ` | R26: No.529 Lanshan East Road,Lanshan District,Rizhao City,China Post Code:276808

Sheet DataBase (IMO form)
B6: No. | C6: Rank | D6: Family Name | E6: Given Name | F6: Middle Initial | G6: Full Middle Name | H6: Gender Passport | I6: Date of Birth | J6: Age | K6: Place of Birth (Passport) | L6: Nationality (Passport) | M6: Country of Birth (Passport) | N6: Nationality (Singapore format) | P6: Date of SEA signed | Q6: Expiration of contract - date | R6: Contract Duration | T6: Embarkation Date | U6: Port of Embarkation | W6: Passport | Z6: U.S. Visa | AD6: National Seaman`s Book | AF6: Marshall Seaman`s Book | AI6: Marshall Endorsement Certificate Expiry Date | AJ6: Type (Original, CRA or Copy) | AL6: Cash | AO6: Crew Effects
W7: Number | X7: Expiry Date | Y7: Issuing State | Z7: Control Number | AA7: Foil Number | AB7: Expiry Date | AD7: Number | AE7: Expiry date | AF7: Number | AG7: Expiry date | AH7: Type (Original, CRA or Copy) | AL7: Dollars | AM7: Euro | AN7: Other
B8: 1 | C8: MASTER | D8: WENDT | E8: ROBERT KRZYSZTOF | H8: M | I8: 31616 | J8: =INT((P8-'DataBase (IMO form)'!I8)/365) -> 39 | K8: GDANSK | L8: POLISH | M8: POLAND | N8: POL | P8: 46030 | Q8: =DATE(YEAR(P8),MONTH(P8)+R8,DAY(P8)-1) -> 46119 | R8: 3 | S8: months | T8: 46002 | U8: DAMIETTA,EGYPT | W8: EK 0855330 | X8: 46330 | Y8: WOJEWODA, POMORSKI | Z8: 20180037080001 | AA8: N0290642 | AB8: 46754 | AD8: AA0009998 | AE8: 48277 | AF8: MH 970901 | AG8: 46896 | AH8: Original | AI8: 46419 | AJ8: Original | AO8: 2 Mobile phones, 1 Laptop, 1 Watch, 1 Gold ring, 1 Necklace | AS8: Original | AT8: Original
B9: 2 | C9: CHIEF OFF | D9: THANASIS | E9: EVANGELOS | H9: M | I9: 34373 | J9: =INT((P9-'DataBase (IMO form)'!I9)/365) -> 32 | K9: KERKYRA | L9: HELLENIC | M9: GREECE | N9: GRC | P9: 46081 | Q9: =DATE(YEAR(P9),MONTH(P9)+R9,DAY(P9)-1) -> 46169 | R9: 3 | S9: months | T9: 46081 | U9: BARCARENA, BRAZIL | W9: BA8948788 | X9: 49542 | Y9: KERKYRA | AD9: E00363 | AE9: Lifetime | AH9: Original | AJ9: Original | AS9: CRA | AT9: CRA
B10: 3 | C10: TR CHIEF OFF | D10: TEJU | E10: TOMA | H10: M | I10: 32970 | J10: =INT((P10-'DataBase (IMO form)'!I10)/365) -> 35 | K10: COSTANTA | L10: ROMANIAN | M10: ROMANIA | N10: ROU | P10: 46081 | Q10: =DATE(YEAR(P10),MONTH(P10)+R10,DAY(P10)-1) -> 46200 | R10: 4 | S10: months | T10: 46081 | U10: BARCARENA, BRAZIL | W10: 059130390 | X10: 47775 | Y10: CONSTANTA | AD10: 86891 | AE10: Lifetime | AH10: Original | AJ10: Original
B11: 4 | C11: 2ND OFF | D11: BUTS | E11: KOSTIANTYN | H11: M | I11: 31971 | J11: =INT((P11-'DataBase (IMO form)'!I11)/365) -> 38 | K11: UKRAINE | L11: UKRAINIAN | M11: UKRAINE | N11: UKR | P11: 46033 | Q11: =DATE(YEAR(P11),MONTH(P11)+R11,DAY(P11)-1) -> 46122 | R11: 3 | S11: months | T11: 46035 | U11: FREEPORT, BAHAMAS | W11: GL504758 | X11: 49422 | Y11: 2110 | Z11: 20202627470005 | AA11: R7110556 | AB11: 47743 | AD11: 8600199276 | AE11: 49120 | AF11: MH 904486 | AG11: 46643 | AH11: Original | AI11: 47306 | AJ11: Original | AO11: 3 Mobile phones, 1 Laptop, 3HDD, 3 USB,1 Headphones | AS11: Copy | AT11: Copy
A12: 07 | B12: 5 | C12: 3RD OFF | D12: STAMATIOU | E12: VASILEIOS | H12: M | I12: 37225 | J12: =INT((P12-'DataBase (IMO form)'!I12)/365) -> 24 | K12: MAROUSI | L12: HELLENIC | M12: GREECE | N12: GRC | P12: 46063 | Q12: =DATE(YEAR(P12),MONTH(P12)+R12,DAY(P12)-1) -> 46151 | R12: 3 | S12: months | T12: 46063 | U12: ALTAMIRA, MEXICO | W12: AY1388281 | X12: 48562 | Y12: N.P.C. | AD12: AA 61439 | AE12: Lifetime | AF12: MH 956958 | AG12: 46870 | AH12: Original | AJ12: Original | AO12: 2 Mobile phones, 1 Watch, 1 HDD, 3 USB, 1 Hairclipper | AS12: N/A | AT12: N/A
B13: 6 | C13: 3RD OFF | D13: KOUIMOV | E13: ENTOUARNT OR EDUARD | H13: M | I13: 36547 | J13: =INT((P13-'DataBase (IMO form)'!I13)/365) -> 26 | K13: NAKHODKA | L13: HELLENIC | M13: RUSSIA | N13: GRC | P13: 46042 | Q13: =DATE(YEAR(P13),MONTH(P13)+R13,DAY(P13)-1) -> 46131 | R13: 3 | S13: months | T13: 46042 | U13: GALVESTON, USA | W13: AY4667152 | X13: 48777 | Y13: N.P.C. | Z13: 20190711170001 | AA13: N9856302 | AB13: 47188 | AD13: AA 60496 | AE13: Lifetime | AF13: MH 981628 | AG13: 47003 | AH13: Original | AO13: 2 Mobile phones, 1 Watch, 1 HDD, 3 USB, 1 Hairclipper
B14: 7 | C14: DECK CADET | D14: CHATZIDIMITRIOU | E14: MARIA | H14: F | I14: 37644 | J14: =INT((P14-'DataBase (IMO form)'!I14)/365) -> 23 | K14: THESSALONIKI | L14: HELLENIC | M14: GREECE | N14: GRC | P14: 46042 | Q14: =DATE(YEAR(P14),MONTH(P14)+R14,DAY(P14)-1) -> 46131 | R14: 3 | S14: months | T14: 46042 | U14: GALVESTON, USA | W14: AT5546138 | X14: 46511 | Y14: N.P.C. | Z14: 20253082630001 | AA14: W2601140 | AB14: 49618 | AD14: ST 39373 | AE14: Lifetime | AF14: MH 1101404 | AG14: 47560 | AH14: Original | AO14: 2 Mobile phones, 1 Watch,1 Laptop
A15: 26- | B15: 8 | C15: CHIEF ENG | D15: PETROPOULOS | E15: CHRISTOS | H15: M | I15: 24483 | J15: =INT((P15-'DataBase (IMO form)'!I15)/365) -> 58 | K15: KOZANI | L15: HELLENIC | M15: GREECE | N15: GRC | P15: 46005 | Q15: =DATE(YEAR(P15),MONTH(P15)+R15,DAY(P15)-1) -> 46094 | R15: 3 | S15: months | T15: 46006 | U15: KALOI LIMENES,GREECE | W15: BA2822002 | X15: 49133 | Y15: H.P.H./P.S.D.D. | Z15: 20250179440001 | AA15: v2048085 | AB15: 49325 | AD15: CY278178 | AE15: 46683 | AF15: MH 859292 | AG15: 46488 | AH15: Original | AI15: 46345 | AJ15: Original | AO15: 1 Laptop, 1 Mobile phone
A16: 26- | B16: 9 | C16: 2ND ENG | D16: SYTNYK | E16: YEVGENIY | H16: M | I16: 32852 | J16: =INT((P16-'DataBase (IMO form)'!I16)/365) -> 35 | K16: ODESSA | L16: UKRAINIAN | M16: UKRAINE | N16: UKR | P16: 45979 | Q16: =DATE(YEAR(P16),MONTH(P16)+R16,DAY(P16)-1) -> 46070 | R16: 3 | S16: months | T16: 45980 | U16: SABINE PASS, USA | W16: GD461450 | X16: 48424 | Y16: 5116 | Z16: 20202200040007 | AA16: P7109132 | AB16: 47701 | AD16: AB 676379 | AE16: 46128 | AF16: MH 11469449 | AG16: 47798 | AH16: Original | AI16: 46064 | AJ16: CRA | AO16: 1 Mobile phone, 1 Laptop, 2 HDD
B17: 10 | C17: 3RD ENG | D17: KACHUR | E17: MYKOLA | H17: M | I17: 35418 | J17: =INT((P17-'DataBase (IMO form)'!I17)/365) -> 29 | K17: UKRAINE | L17: UKRAINIAN | M17: UKRAINE | N17: UKR | P17: 46033 | Q17: =DATE(YEAR(P17),MONTH(P17)+R17,DAY(P17)-1) -> 46122 | R17: 3 | S17: months | T17: 46035 | U17: FREEPORT, BAHAMAS | W17: FS151214 | X17: 46978 | Y17: 6512 | Z17: 20180023650001 | AA17: N0085660 | AB17: 46753 | AD17: AA 1002553 | AE17: 47308 | AF17: MH 77412 | AG17: 46091 | AH17: Original | AI17: 47093 | AJ17: Original | AO17: 2 Mobile phones,1 Laptop, 1 shaver, 1 HDD, 1 SSD, I USB, 1 erigator
B18: 11 | C18: 3RD ENG | D18: COLEASA | E18: STEFAN CIPRIAN | H18: M | I18: 33966 | J18: =INT((P18-'DataBase (IMO form)'!I18)/365) -> 33 | K18: CONSTANTA | L18: ROMANIAN | M18: ROMANIA | N18: ROU | P18: 46063 | Q18: =DATE(YEAR(P18),MONTH(P18)+R18,DAY(P18)-1) -> 46151 | R18: 3 | S18: months | T18: 45912 | U18: ALTAMIRA, MEXICO | W18: 063513795 | X18: 48638 | Y18: CONSTANTA | AD18: 31553CT | AE18: 46583 | AH18: Original | AJ18: Original | AO18: 2 Mobile phones, 1 Laptop, 1 HDD, 1 SSD, 3 USB, 2 Wrist watch, 1 Hairclipper, 1 Powerbank, 3 Flashlights
B19: 12 | C19: 4TH ENG | D19: LOFTSALIS | E19: APOSTOLOS | H19: M | I19: 37555 | J19: =INT((P19-'DataBase (IMO form)'!I19)/365) -> 23 | K19: KOZANI | L19: HELLENIC | M19: GREECE | N19: GRC | P19: 46042 | Q19: =DATE(YEAR(P19),MONTH(P19)+R19,DAY(P19)-1) -> 46072 | R19: 1 | S19: months | T19: 46042 | U19: GALVESTON, USA | W19: BB0444273 | X19: 49626 | Y19: H.P.H./P.S.D.D. | Z19: 20250566280001 | AA19: V2048763 | AB19: 49364 | AD19: ST39185 | AE19: Lifetime | AF19: MH 1024999 | AG19: 47203 | AH19: Original | AO19: 2 Mobile phones, 1 Laptop, 2 Watches, 2 HDD, 1 Gold Ring,
B20: 13 | C20: GAS ENG | D20: YEMELIANOV | E20: RICHARD | H20: M | I20: 32955 | J20: =INT((P20-'DataBase (IMO form)'!I20)/365) -> 35 | K20: UKRAINE | L20: UKRAINIAN | M20: UKRAINE | N20: UKR | P20: 46035 | Q20: =DATE(YEAR(P20),MONTH(P20)+R20,DAY(P20)-1) -> 46124 | R20: 3 | S20: months | T20: 46035 | U20: FREEPORT, BAHAMAS | W20: FJ899634 | X20: 46699 | Y20: 5101 | Z20: 20173258560001 | AA20: M7306443 | AB20: 46711 | AD20: AB623826 | AE20: 46685 | AF20: MH 925122 | AG20: 46741 | AH20: Original | AI20: 47468 | AJ20: Original | AO20: 1 Mobile phone, 1 Laptop, 1 HDD, 1 Hairclipper
B21: 14 | C21: SETO | D21: GIDEI | E21: NICOLAE | H21: M | I21: 27720 | J21: =INT((P21-'DataBase (IMO form)'!I21)/365) -> 50 | K21: GALATI | L21: ROMANIAN | M21: ROMANIA | N21: ROU | P21: 46042 | Q21: =DATE(YEAR(P21),MONTH(P21)+R21,DAY(P21)-1) -> 46131 | R21: 3 | S21: months | T21: 46042 | U21: GALVESTON, USA | W21: 056799980 | X21: 47104 | Y21: GALATI | Z21: 20253431690001 | AA21: W3578177 | AB21: 49651 | AD21: 4695GL | AE21: 47073 | AF21: MH 916167 | AG21: 46740 | AH21: Original | AO21: 2 Mobile phones, 1 Laptop
B22: 15 | C22: BOSUN | D22: LADINES | E22: RODOLFO JR. | H22: M | I22: 29241 | J22: =INT((P22-'DataBase (IMO form)'!I22)/365) -> 46 | K22: SAMPALOC QUEZON | L22: FILIPINO | M22: PHILIPPINES | N22: PHL | P22: 46081 | Q22: =DATE(YEAR(P22),MONTH(P22)+R22,DAY(P22)-1) -> 46353 | R22: 9 | S22: months | T22: 46081 | U22: BARCARENA, BRAZIL | W22: P9127792B | X22: 48275 | Y22: DFA LUCENA | AD22: A0495660 | AE22: 49701 | AH22: Original | AI22: N/A | AJ22: N/A | AO22: 1 Laptop, 1 Mobile phone
B23: 16 | C23: AB | D23: LUPAZ | E23: ALBERTO JR. | H23: M | I23: 34168 | J23: =INT((P23-'DataBase (IMO form)'!I23)/365) -> 32 | K23: NASIPIT AND | L23: FILIPINO | M23: PHILIPPINES | N23: PHL | P23: 46081 | Q23: =DATE(YEAR(P23),MONTH(P23)+R23,DAY(P23)-1) -> 46353 | R23: 9 | S23: months | T23: 46081 | U23: BARCARENA, BRAZIL | W23: P5223721B | X23: 47649 | Y23: DFA NCR WEST | AD23: A0482204 | AE23: 49647 | AH23: Original | AI23: N/A | AJ23: N/A | AO23: 1 Laptop, 1 Mobile phone
B24: 17 | C24: AB | D24: PALERACIO | E24: JOHN CALLED | H24: M | I24: 33759 | J24: =INT((P24-'DataBase (IMO form)'!I24)/365) -> 33 | K24: SAMPALOC QUEZON | L24: FILIPINO | M24: PHILIPPINES | N24: PHL | P24: 46081 | Q24: =DATE(YEAR(P24),MONTH(P24)+R24,DAY(P24)-1) -> 46353 | R24: 9 | S24: months | T24: 46081 | U24: BARCARENA, BRAZIL | W24: P5914768B | X24: 47825 | Y24: DFA LUCENA | AD24: A0120246 | AE24: 47862 | AH24: Original | AI24: N/A | AJ24: N/A | AO24: 1 Laptop, 1 Mobile phone
B25: 18 | C25: AB | D25: RUFON | E25: NOEL III | F25: S | G25: SUPIL | H25: M | I25: 35899 | J25: =INT((P25-'DataBase (IMO form)'!I25)/365) -> 27 | K25: QUEZON CITY | L25: FILIPINO | M25: PHILIPPINES | N25: PHL | P25: 45938 | Q25: =DATE(YEAR(P25),MONTH(P25)+R25,DAY(P25)-1) -> 46210 | R25: 9 | S25: months | T25: 45957 | U25: MUKRAN,GERMANY | W25: P3324286B | X25: 47384 | Y25: DFA NCR NORTHEAST | AD25: C1227075 | AE25: 47384 | AF25: MH 994967 | AG25: 47059 | AH25: Original | AI25: N/A | AJ25: N/A | AO25: 2 Mobile Phones, 2 Watches
B26: 19 | C26: AB | D26: CASTILLO | E26: TIMBERT | H26: M | I26: 34015 | J26: =INT((P26-'DataBase (IMO form)'!I26)/365) -> 33 | K26: BUENAVISTA MDQ | L26: FILIPINO | M26: PHILIPPINES | N26: PHL | P26: 46081 | Q26: =DATE(YEAR(P26),MONTH(P26)+R26,DAY(P26)-1) -> 46383 | R26: 10 | S26: months | T26: 46081 | U26: BARCARENA, BRAZIL | W26: P4666149B | X26: 47516 | Y26: DFA MANILA | AD26: C1195674 | AE26: 46853 | AH26: Original | AI26: N/A | AJ26: N/A | AO26: 1 Laptop, 1 Mobile phone
B27: 20 | C27: OS | D27: ACULIT | E27: MIKE LISLIE | F27: P | G27: PELLION | H27: M | I27: 35054 | J27: =INT((P27-'DataBase (IMO form)'!I27)/365) -> 29 | K27: BAGO CITY | L27: FILIPINO | M27: PHILIPPINES | N27: PHL | P27: 45826 | Q27: =DATE(YEAR(P27),MONTH(P27)+R27,DAY(P27)-1) -> 46098 | R27: 9 | S27: months | T27: 45830 | U27: WILHELMSHAVEN, GERMANY | W27: P3505092B | X27: 47401 | Y27: DFA BACOLOD | AD27: C1401071 | AE27: 47031 | AF27: MH 1065960 | AG27: 47378 | AH27: Copy | AI27: N/A | AJ27: N/A | AO27: 2 Mobile phones, 1 Speaker, 1 Watch, 1 Hairclipper, 1 Airpods
B28: 21 | C28: OS | D28: DOMONDON | E28: DEXTER | F28: S | G28: SANTOS | H28: M | I28: 36084 | J28: =INT((P28-'DataBase (IMO form)'!I28)/365) -> 27 | K28: MARIKINA CITY | L28: FILIPINO | M28: PHILIPPINES | N28: PHL | P28: 45974 | Q28: =DATE(YEAR(P28),MONTH(P28)+R28,DAY(P28)-1) -> 46065 | R28: 3 | S28: months | T28: 45980 | U28: SABINE PASS, USA | W28: P6400609A | X28: 46824 | Y28: DFA NCR WEST | Z28: 20252259030269 | AA28: V8070643 | AB28: 49532 | AD28: C1518575 | AE28: 47311 | AF28: MH 1159248 | AG28: 47807 | AH28: Original | AI28: N/A | AJ28: N/A | AO28: 2 Mobile phone, 1 HDD 1 Watch, Earrings
B29: 22 | C29: FITTER | D29: DACANAY | E29: JAYSON | F29: L | G29: LALATA | H29: M | I29: 33621 | J29: =INT((P29-'DataBase (IMO form)'!I29)/365) -> 33 | K29: SISON PANGASINAN | L29: FILIPINO | M29: PHILIPPINES | N29: PHL | P29: 45921 | Q29: =DATE(YEAR(P29),MONTH(P29)+R29,DAY(P29)-1) -> 46101 | R29: 6 | S29: months | T29: 45830 | U29: WILHELMSHAVEN, GERMANY | W29: P6556840B | X29: 47931 | Y29: DFA LA UNION | AD29: C1033223 | AE29: 46492 | AF29: MH 972208 | AG29: 46947 | AH29: Original | AI29: N/A | AJ29: N/A | AO29: 2 Mobile phones,1 Tablet, 1 Watch, 1 Hairclipper, 1 Earpods, 1 HDD, 1 Ring, 1 Wrist watch
B30: 23 | C30: MTM | D30: APID | E30: LORD BYRON | F30: A | G30: ARGONSOLA | H30: M | I30: 32630 | J30: =INT((P30-'DataBase (IMO form)'!I30)/365) -> 36 | K30: DIONISIO ILOILO | L30: FILIPINO | M30: PHILIPPINES | N30: PHL | P30: 45895 | Q30: =DATE(YEAR(P30),MONTH(P30)+R30,DAY(P30)-1) -> 46167 | R30: 9 | S30: months | T30: 45957 | U30: MUKRAN,GERMANY | W30: P6351015A | X30: 46820 | Y30: DFA MANILA | AD30: C1017743 | AE30: 46820 | AF30: MH 995403 | AG30: 47064 | AH30: Original | AI30: N/A | AJ30: N/A | AO30: 2 Mobile Phones, 1 Laptop, BT Mouse, 1 Gold ring, 2 usb, 1 HDD
B31: 24 | C31: MTM | D31: BRILLANTES | E31: FER ANN | F31: C | G31: CADIZ | H31: M | I31: 33831 | J31: =INT((P31-'DataBase (IMO form)'!I31)/365) -> 33 | K31: ILOILO CITY | L31: FILIPINO | M31: PHILIPPINES | N31: PHL | P31: 45974 | Q31: =DATE(YEAR(P31),MONTH(P31)+R31,DAY(P31)-1) -> 46065 | R31: 3 | S31: months | T31: 45980 | U31: SABINE PASS, USA | W31: P7519115A | X31: 46914 | Y31: DFA ILOILO | Z31: 20252756310225 | AA31: V8123508 | AB31: 49583 | AD31: A0106824 | AE31: 47895 | AF31: MH 879873 | AG31: 46606 | AH31: Original | AI31: N/A | AJ31: N/A | AO31: 2 Mobile Phones, 1 Laptop, 3 HDD
B32: 25 | C32: WIPER | D32: FLORES | E32: NORIEL | F32: A | G32: AMORADO | H32: M | I32: 36550 | J32: =INT((P32-'DataBase (IMO form)'!I32)/365) -> 25 | K32: P GALERA OR MDO | L32: FILIPINO | M32: PHILIPPINES | N32: PHL | P32: 45993 | Q32: =DATE(YEAR(P32),MONTH(P32)+R32,DAY(P32)-1) -> 46082 | R32: 3 | S32: months | T32: 46002 | U32: DAMIETTA,EGYPT | W32: P1950890C | X32: 48494 | Y32: DFA NCR SOUTH | Z32: 20233324880021 | AA32: T5060249 | AB32: 48910 | AD32: A0277972 | AE32: 48792 | AF32: MH 1020115 | AG32: 47180 | AH32: Original | AI32: N/A | AJ32: N/A | AO32: 2 Mobile phones, 1 Watch
B33: 26 | C33: CHIEF COOK | D33: ESTRABELA | E33: ARIES | F33: E | G33: ESPINAR | H33: M | I33: 34876 | J33: =INT((P33-'DataBase (IMO form)'!I33)/365) -> 30 | K33: BARCELONA SSG | L33: FILIPINO | M33: PHILIPPINES | N33: PHL | P33: 45950 | Q33: =DATE(YEAR(P33),MONTH(P33)+R33,DAY(P33)-1) -> 46222 | R33: 9 | S33: months | T33: 45957 | U33: MUKRAN,GERMANY | W33: P6676452B | X33: 47957 | Y33: DFA NCR EAST | Z33: 20252068330068 | AA33: V8071612 | AB33: 49533 | AD33: A0353766 | AE33: 49508 | AF33: MH 972207 | AG33: 46947 | AH33: Original | AI33: N/A | AJ33: N/A | AO33: 2 Mobile Phones, 1 Laptop, 1 BT speaker, 1HDD, 3 USB
B34: 27 | C34: ASS COOK | D34: ALLADO | E34: KEITH VINCENT | H34: M | I34: 34074 | J34: =INT((P34-'DataBase (IMO form)'!I34)/365) -> 32 | K34: SAMPALOC QUEZON | L34: FILIPINO | M34: PHILIPPINES | N34: PHL | P34: 46081 | Q34: =DATE(YEAR(P34),MONTH(P34)+R34,DAY(P34)-1) -> 46353 | R34: 9 | S34: months | T34: 46081 | U34: BARCARENA, BRAZIL | W34: P6096925B | X34: 47862 | Y34: DFA LUCENA | AD34: A0449605 | AE34: 49694 | AH34: Original | AI34: N/A | AJ34: N/A | AO34: 2 Mobile phones, 1 USB, 1 Earphones
B35: 28 | C35: MSM | D35: ABES | E35: JAMES DARWIN | F35: A | G35: ACURAM | H35: M | I35: 36409 | J35: =INT((P35-'DataBase (IMO form)'!I35)/365) -> 26 | K35: GITAGUM MIS OR | L35: FILIPINO | M35: PHILIPPINES | N35: PHL | P35: 45921 | Q35: =DATE(YEAR(P35),MONTH(P35)+R35,DAY(P35)-1) -> 46101 | R35: 6 | S35: months | T35: 45830 | U35: WILHELMSHAVEN, GERMANY | W35: P3071209C | X35: 48604 | Y35: DFA BUTUAN | AD35: A0067860 | AE35: 48424 | AF35: MH 1123766 | AG35: 47119 | AH35: Copy | AI35: N/A | AJ35: N/A | AO35: 1 Mobile phone,1 Earphone, 1 Powerbank, 1 Smartwatch, 1 Speaker, OTG

Sheet Arr Crew List IMO
B2: IMO CREW LIST
B3: IMO FAL FORM 5
L4: Page No.
F5: Arrival Departure | L5: 1/1
B6: 1.1 Name of ship | D6: =M.Menu!E3 -> Energy Endurance | F6: 2. Port of arrival/departure | I6: 3. Date of arrival/departure
B7: 1.2 IMO number | D7: 9859739 | F7: =M.Menu!L11&", "&M.Menu!L12 -> Sabine Pass, U.S.A. | I7: =M.Menu!L13 -> 46106
B8: 1.3 Call sign | D8: =M.Menu!E4 -> V7A7282 | F8: =M.Menu!E8&", "&M.Menu!E9 -> NFE Transport Partners LLC,
B9: 1.4 Voyage number | D9: =M.Menu!S13 -> VOY16
B10: 4. Flag State of ship | F10: 5. Last port of call
B11: =M.Menu!L8 -> Marshall Islands | F11: =M.Menu!E11&", "&M.Menu!E12 -> BARCARENA, BRAZIL
B12: 6. No. | C12: 7. Family name | D12: 8. Given names | E12: 9. Rank or rating | F12: 10. Nationality | G12: 11. Date of birth | H12: 12. Place of birth | J12: 13. Gender | K12: 14. Nature of identity document | L12: 15. Number of identity document | M12: 16. Issuing State of identity document | N12: 17. Expiry date of identity document
B14: ='DataBase (IMO form)'!B8 -> 1 | C14: ='DataBase (IMO form)'!D8 -> WENDT | D14: ='DataBase (IMO form)'!E8 -> ROBERT KRZYSZTOF | E14: ='DataBase (IMO form)'!C8 -> MASTER | F14: ='DataBase (IMO form)'!L8 -> POLISH | G14: ='DataBase (IMO form)'!I8 -> 31616 | H14: ='DataBase (IMO form)'!K8 -> GDANSK | I14: #REF! | J14: ='DataBase (IMO form)'!H8 -> M | K14: PASSPORT | L14: ='DataBase (IMO form)'!W8 -> EK 0855330 | M14: ='DataBase (IMO form)'!Y8 -> WOJEWODA, POMORSKI | N14: ='DataBase (IMO form)'!X8 -> 46330
B15: ='DataBase (IMO form)'!B9 -> 2 | C15: ='DataBase (IMO form)'!D9 -> THANASIS | D15: ='DataBase (IMO form)'!E9 -> EVANGELOS | E15: ='DataBase (IMO form)'!C9 -> CHIEF OFF | F15: ='DataBase (IMO form)'!L9 -> HELLENIC | G15: ='DataBase (IMO form)'!I9 -> 34373 | H15: ='DataBase (IMO form)'!K9 -> KERKYRA | I15: #REF! | J15: ='DataBase (IMO form)'!H9 -> M | K15: PASSPORT | L15: ='DataBase (IMO form)'!W9 -> BA8948788 | M15: ='DataBase (IMO form)'!Y9 -> KERKYRA | N15: ='DataBase (IMO form)'!X9 -> 49542
B16: ='DataBase (IMO form)'!B10 -> 3 | C16: ='DataBase (IMO form)'!D10 -> TEJU | D16: ='DataBase (IMO form)'!E10 -> TOMA | E16: ='DataBase (IMO form)'!C10 -> TR CHIEF OFF | F16: ='DataBase (IMO form)'!L10 -> ROMANIAN | G16: ='DataBase (IMO form)'!I10 -> 32970 | H16: ='DataBase (IMO form)'!K10 -> COSTANTA | I16: #REF! | J16: ='DataBase (IMO form)'!H10 -> M | K16: PASSPORT | L16: ='DataBase (IMO form)'!W10 -> 059130390 | M16: ='DataBase (IMO form)'!Y10 -> CONSTANTA | N16: ='DataBase (IMO form)'!X10 -> 47775
B17: ='DataBase (IMO form)'!B11 -> 4 | C17: ='DataBase (IMO form)'!D11 -> BUTS | D17: ='DataBase (IMO form)'!E11 -> KOSTIANTYN | E17: ='DataBase (IMO form)'!C11 -> 2ND OFF | F17: ='DataBase (IMO form)'!L11 -> UKRAINIAN | G17: ='DataBase (IMO form)'!I11 -> 31971 | H17: ='DataBase (IMO form)'!K11 -> UKRAINE | I17: #REF! | J17: ='DataBase (IMO form)'!H11 -> M | K17: PASSPORT | L17: ='DataBase (IMO form)'!W11 -> GL504758 | M17: ='DataBase (IMO form)'!Y11 -> 2110 | N17: ='DataBase (IMO form)'!X11 -> 49422
B18: ='DataBase (IMO form)'!B12 -> 5 | C18: ='DataBase (IMO form)'!D12 -> STAMATIOU | D18: ='DataBase (IMO form)'!E12 -> VASILEIOS | E18: ='DataBase (IMO form)'!C12 -> 3RD OFF | F18: ='DataBase (IMO form)'!L12 -> HELLENIC | G18: ='DataBase (IMO form)'!I12 -> 37225 | H18: ='DataBase (IMO form)'!K12 -> MAROUSI | I18: #REF! | J18: ='DataBase (IMO form)'!H12 -> M | K18: PASSPORT | L18: ='DataBase (IMO form)'!W12 -> AY1388281 | M18: ='DataBase (IMO form)'!Y12 -> N.P.C. | N18: ='DataBase (IMO form)'!X12 -> 48562
B19: ='DataBase (IMO form)'!B13 -> 6 | C19: ='DataBase (IMO form)'!D13 -> KOUIMOV | D19: ='DataBase (IMO form)'!E13 -> ENTOUARNT OR EDUARD | E19: ='DataBase (IMO form)'!C13 -> 3RD OFF | F19: ='DataBase (IMO form)'!L13 -> HELLENIC | G19: ='DataBase (IMO form)'!I13 -> 36547 | H19: ='DataBase (IMO form)'!K13 -> NAKHODKA | I19: #REF! | J19: ='DataBase (IMO form)'!H13 -> M | K19: PASSPORT | L19: ='DataBase (IMO form)'!W13 -> AY4667152 | M19: ='DataBase (IMO form)'!Y13 -> N.P.C. | N19: ='DataBase (IMO form)'!X13 -> 48777
B20: ='DataBase (IMO form)'!B14 -> 7 | C20: ='DataBase (IMO form)'!D14 -> CHATZIDIMITRIOU | D20: ='DataBase (IMO form)'!E14 -> MARIA | E20: ='DataBase (IMO form)'!C14 -> DECK CADET | F20: ='DataBase (IMO form)'!L14 -> HELLENIC | G20: ='DataBase (IMO form)'!I14 -> 37644 | H20: ='DataBase (IMO form)'!K14 -> THESSALONIKI | I20: #REF! | J20: ='DataBase (IMO form)'!H14 -> F | K20: PASSPORT | L20: ='DataBase (IMO form)'!W14 -> AT5546138 | M20: ='DataBase (IMO form)'!Y14 -> N.P.C. | N20: ='DataBase (IMO form)'!X14 -> 46511
B21: ='DataBase (IMO form)'!B15 -> 8 | C21: ='DataBase (IMO form)'!D15 -> PETROPOULOS | D21: ='DataBase (IMO form)'!E15 -> CHRISTOS | E21: ='DataBase (IMO form)'!C15 -> CHIEF ENG | F21: ='DataBase (IMO form)'!L15 -> HELLENIC | G21: ='DataBase (IMO form)'!I15 -> 24483 | H21: ='DataBase (IMO form)'!K15 -> KOZANI | I21: #REF! | J21: ='DataBase (IMO form)'!H15 -> M | K21: PASSPORT | L21: ='DataBase (IMO form)'!W15 -> BA2822002 | M21: ='DataBase (IMO form)'!Y15 -> H.P.H./P.S.D.D. | N21: ='DataBase (IMO form)'!X15 -> 49133
B22: ='DataBase (IMO form)'!B16 -> 9 | C22: ='DataBase (IMO form)'!D16 -> SYTNYK | D22: ='DataBase (IMO form)'!E16 -> YEVGENIY | E22: ='DataBase (IMO form)'!C16 -> 2ND ENG | F22: ='DataBase (IMO form)'!L16 -> UKRAINIAN | G22: ='DataBase (IMO form)'!I16 -> 32852 | H22: ='DataBase (IMO form)'!K16 -> ODESSA | I22: #REF! | J22: ='DataBase (IMO form)'!H16 -> M | K22: PASSPORT | L22: ='DataBase (IMO form)'!W16 -> GD461450 | M22: ='DataBase (IMO form)'!Y16 -> 5116 | N22: ='DataBase (IMO form)'!X16 -> 48424
B23: ='DataBase (IMO form)'!B17 -> 10 | C23: ='DataBase (IMO form)'!D17 -> KACHUR | D23: ='DataBase (IMO form)'!E17 -> MYKOLA | E23: ='DataBase (IMO form)'!C17 -> 3RD ENG | F23: ='DataBase (IMO form)'!L17 -> UKRAINIAN | G23: ='DataBase (IMO form)'!I17 -> 35418 | H23: ='DataBase (IMO form)'!K17 -> UKRAINE | I23: #REF! | J23: ='DataBase (IMO form)'!H17 -> M | K23: PASSPORT | L23: ='DataBase (IMO form)'!W17 -> FS151214 | M23: ='DataBase (IMO form)'!Y17 -> 6512 | N23: ='DataBase (IMO form)'!X17 -> 46978
B24: ='DataBase (IMO form)'!B18 -> 11 | C24: ='DataBase (IMO form)'!D18 -> COLEASA | D24: ='DataBase (IMO form)'!E18 -> STEFAN CIPRIAN | E24: ='DataBase (IMO form)'!C18 -> 3RD ENG | F24: ='DataBase (IMO form)'!L18 -> ROMANIAN | G24: ='DataBase (IMO form)'!I18 -> 33966 | H24: ='DataBase (IMO form)'!K18 -> CONSTANTA | I24: #REF! | J24: ='DataBase (IMO form)'!H18 -> M | K24: PASSPORT | L24: ='DataBase (IMO form)'!W18 -> 063513795 | M24: ='DataBase (IMO form)'!Y18 -> CONSTANTA | N24: ='DataBase (IMO form)'!X18 -> 48638
B25: ='DataBase (IMO form)'!B19 -> 12 | C25: ='DataBase (IMO form)'!D19 -> LOFTSALIS | D25: ='DataBase (IMO form)'!E19 -> APOSTOLOS | E25: ='DataBase (IMO form)'!C19 -> 4TH ENG | F25: ='DataBase (IMO form)'!L19 -> HELLENIC | G25: ='DataBase (IMO form)'!I19 -> 37555 | H25: ='DataBase (IMO form)'!K19 -> KOZANI | I25: #REF! | J25: ='DataBase (IMO form)'!H19 -> M | K25: PASSPORT | L25: ='DataBase (IMO form)'!W19 -> BB0444273 | M25: ='DataBase (IMO form)'!Y19 -> H.P.H./P.S.D.D. | N25: ='DataBase (IMO form)'!X19 -> 49626
... B42: ='DataBase (IMO form)'!B36 -> 0 | C42: ='DataBase (IMO form)'!D36 -> 0 | D42: ='DataBase (IMO form)'!E36 -> 0 | E42: ='DataBase (IMO form)'!C36 -> 0 | F42: ='DataBase (IMO form)'!L36 -> 0 | G42: ='DataBase (IMO form)'!I36 -> 0 | H42: ='DataBase (IMO form)'!K36 -> 0 | I42: #REF! | J42: ='DataBase (IMO form)'!H36 -> 0 | K42: PASSPORT | L42: ='DataBase (IMO form)'!W36 -> 0 | M42: ='DataBase (IMO form)'!Y36 -> 0 | N42: ='DataBase (IMO form)'!X36 -> 0
B43: ='DataBase (IMO form)'!B36 -> 0 | C43: ='DataBase (IMO form)'!D36 -> 0 | D43: ='DataBase (IMO form)'!E36 -> 0 | E43: ='DataBase (IMO form)'!C36 -> 0 | F43: ='DataBase (IMO form)'!L36 -> 0 | G43: ='DataBase (IMO form)'!I36 -> 0 | H43: ='DataBase (IMO form)'!K36 -> 0 | I43: #REF! | J43: ='DataBase (IMO form)'!H36 -> 0 | K43: PASSPORT | L43: ='DataBase (IMO form)'!W36 -> 0 | M43: ='DataBase (IMO form)'!Y36 -> 0 | N43: ='DataBase (IMO form)'!X36 -> 0
B44: 18. Date and signature by master, authorized agent or officer
C46: =I7 -> 46106
G47: =M.Menu!S16 -> CAPT. WENDT ROBERT
G48: M a s t e r

Sheet Arr Crew List Port
A2: IMO CREW LIST
A3: IMO FAL FORM 5
L4: Page No.
F5: Arrival Departure | L5: 1/1
B6: 1.1 Name of ship | D6: =M.Menu!E3 -> Energy Endurance | F6: 2. Port of arrival/departure | I6: 3. Date of arrival/departure
B7: 1.2 IMO number | D7: 9859739 | F7: =M.Menu!L11&", "&M.Menu!L12 -> Sabine Pass, U.S.A. | I7: =M.Menu!L13 -> 46106
B8: 1.3 Call sign | D8: =M.Menu!E4 -> V7A7282 | F8: =M.Menu!E8&", "&M.Menu!E9 -> NFE Transport Partners LLC,
B9: 1.4 Voyage number | D9: =M.Menu!S13 -> VOY16
B10: 4. Flag State of ship | F10: 5. Last port of call
B11: =M.Menu!L8 -> Marshall Islands | F11: =M.Menu!E11&", "&M.Menu!E12 -> BARCARENA, BRAZIL
B12: 6. No. | C12: 7. Family name | D12: 8. Given names | E12: 9. Rank or rating | F12: 10. Nationality | G12: 11. Embarkation date | H12: 12. Embarkation port | J12: 13. Gender | K12: 14. Nature of identity document | L12: 15. Number of identity document | M12: 16. Issuing State of identity document | N12: 17. Expiry date of identity document
B14: ='DataBase (IMO form)'!B8 -> 1 | C14: ='DataBase (IMO form)'!D8 -> WENDT | D14: ='DataBase (IMO form)'!E8 -> ROBERT KRZYSZTOF | E14: ='DataBase (IMO form)'!C8 -> MASTER | F14: ='DataBase (IMO form)'!L8 -> POLISH | G14: ='DataBase (IMO form)'!T8 -> 46002 | H14: ='DataBase (IMO form)'!U8 -> DAMIETTA,EGYPT | I14: #REF! | J14: ='DataBase (IMO form)'!H8 -> M | K14: PASSPORT | L14: ='DataBase (IMO form)'!W8 -> EK 0855330 | M14: ='DataBase (IMO form)'!Y8 -> WOJEWODA, POMORSKI | N14: ='DataBase (IMO form)'!X8 -> 46330
B15: ='DataBase (IMO form)'!B9 -> 2 | C15: ='DataBase (IMO form)'!D9 -> THANASIS | D15: ='DataBase (IMO form)'!E9 -> EVANGELOS | E15: ='DataBase (IMO form)'!C9 -> CHIEF OFF | F15: ='DataBase (IMO form)'!L9 -> HELLENIC | G15: ='DataBase (IMO form)'!T9 -> 46081 | H15: ='DataBase (IMO form)'!U9 -> BARCARENA, BRAZIL | I15: #REF! | J15: ='DataBase (IMO form)'!H9 -> M | K15: PASSPORT | L15: ='DataBase (IMO form)'!W9 -> BA8948788 | M15: ='DataBase (IMO form)'!Y9 -> KERKYRA | N15: ='DataBase (IMO form)'!X9 -> 49542
B16: ='DataBase (IMO form)'!B10 -> 3 | C16: ='DataBase (IMO form)'!D10 -> TEJU | D16: ='DataBase (IMO form)'!E10 -> TOMA | E16: ='DataBase (IMO form)'!C10 -> TR CHIEF OFF | F16: ='DataBase (IMO form)'!L10 -> ROMANIAN | G16: ='DataBase (IMO form)'!T10 -> 46081 | H16: ='DataBase (IMO form)'!U10 -> BARCARENA, BRAZIL | I16: #REF! | J16: ='DataBase (IMO form)'!H10 -> M | K16: PASSPORT | L16: ='DataBase (IMO form)'!W10 -> 059130390 | M16: ='DataBase (IMO form)'!Y10 -> CONSTANTA | N16: ='DataBase (IMO form)'!X10 -> 47775
B17: ='DataBase (IMO form)'!B11 -> 4 | C17: ='DataBase (IMO form)'!D11 -> BUTS | D17: ='DataBase (IMO form)'!E11 -> KOSTIANTYN | E17: ='DataBase (IMO form)'!C11 -> 2ND OFF | F17: ='DataBase (IMO form)'!L11 -> UKRAINIAN | G17: ='DataBase (IMO form)'!T11 -> 46035 | H17: ='DataBase (IMO form)'!U11 -> FREEPORT, BAHAMAS | I17: #REF! | J17: ='DataBase (IMO form)'!H11 -> M | K17: PASSPORT | L17: ='DataBase (IMO form)'!W11 -> GL504758 | M17: ='DataBase (IMO form)'!Y11 -> 2110 | N17: ='DataBase (IMO form)'!X11 -> 49422
B18: ='DataBase (IMO form)'!B12 -> 5 | C18: ='DataBase (IMO form)'!D12 -> STAMATIOU | D18: ='DataBase (IMO form)'!E12 -> VASILEIOS | E18: ='DataBase (IMO form)'!C12 -> 3RD OFF | F18: ='DataBase (IMO form)'!L12 -> HELLENIC | G18: ='DataBase (IMO form)'!T12 -> 46063 | H18: ='DataBase (IMO form)'!U12 -> ALTAMIRA, MEXICO | I18: #REF! | J18: ='DataBase (IMO form)'!H12 -> M | K18: PASSPORT | L18: ='DataBase (IMO form)'!W12 -> AY1388281 | M18: ='DataBase (IMO form)'!Y12 -> N.P.C. | N18: ='DataBase (IMO form)'!X12 -> 48562
B19: ='DataBase (IMO form)'!B13 -> 6 | C19: ='DataBase (IMO form)'!D13 -> KOUIMOV | D19: ='DataBase (IMO form)'!E13 -> ENTOUARNT OR EDUARD | E19: ='DataBase (IMO form)'!C13 -> 3RD OFF | F19: ='DataBase (IMO form)'!L13 -> HELLENIC | G19: ='DataBase (IMO form)'!T13 -> 46042 | H19: ='DataBase (IMO form)'!U13 -> GALVESTON, USA | I19: #REF! | J19: ='DataBase (IMO form)'!H13 -> M | K19: PASSPORT | L19: ='DataBase (IMO form)'!W13 -> AY4667152 | M19: ='DataBase (IMO form)'!Y13 -> N.P.C. | N19: ='DataBase (IMO form)'!X13 -> 48777
B20: ='DataBase (IMO form)'!B14 -> 7 | C20: ='DataBase (IMO form)'!D14 -> CHATZIDIMITRIOU | D20: ='DataBase (IMO form)'!E14 -> MARIA | E20: ='DataBase (IMO form)'!C14 -> DECK CADET | F20: ='DataBase (IMO form)'!L14 -> HELLENIC | G20: ='DataBase (IMO form)'!T14 -> 46042 | H20: ='DataBase (IMO form)'!U14 -> GALVESTON, USA | I20: #REF! | J20: ='DataBase (IMO form)'!H14 -> F | K20: PASSPORT | L20: ='DataBase (IMO form)'!W14 -> AT5546138 | M20: ='DataBase (IMO form)'!Y14 -> N.P.C. | N20: ='DataBase (IMO form)'!X14 -> 46511
B21: ='DataBase (IMO form)'!B15 -> 8 | C21: ='DataBase (IMO form)'!D15 -> PETROPOULOS | D21: ='DataBase (IMO form)'!E15 -> CHRISTOS | E21: ='DataBase (IMO form)'!C15 -> CHIEF ENG | F21: ='DataBase (IMO form)'!L15 -> HELLENIC | G21: ='DataBase (IMO form)'!T15 -> 46006 | H21: ='DataBase (IMO form)'!U15 -> KALOI LIMENES,GREECE | I21: #REF! | J21: ='DataBase (IMO form)'!H15 -> M | K21: PASSPORT | L21: ='DataBase (IMO form)'!W15 -> BA2822002 | M21: ='DataBase (IMO form)'!Y15 -> H.P.H./P.S.D.D. | N21: ='DataBase (IMO form)'!X15 -> 49133
B22: ='DataBase (IMO form)'!B16 -> 9 | C22: ='DataBase (IMO form)'!D16 -> SYTNYK | D22: ='DataBase (IMO form)'!E16 -> YEVGENIY | E22: ='DataBase (IMO form)'!C16 -> 2ND ENG | F22: ='DataBase (IMO form)'!L16 -> UKRAINIAN | G22: ='DataBase (IMO form)'!T16 -> 45980 | H22: ='DataBase (IMO form)'!U16 -> SABINE PASS, USA | I22: #REF! | J22: ='DataBase (IMO form)'!H16 -> M | K22: PASSPORT | L22: ='DataBase (IMO form)'!W16 -> GD461450 | M22: ='DataBase (IMO form)'!Y16 -> 5116 | N22: ='DataBase (IMO form)'!X16 -> 48424
B23: ='DataBase (IMO form)'!B17 -> 10 | C23: ='DataBase (IMO form)'!D17 -> KACHUR | D23: ='DataBase (IMO form)'!E17 -> MYKOLA | E23: ='DataBase (IMO form)'!C17 -> 3RD ENG | F23: ='DataBase (IMO form)'!L17 -> UKRAINIAN | G23: ='DataBase (IMO form)'!T17 -> 46035 | H23: ='DataBase (IMO form)'!U17 -> FREEPORT, BAHAMAS | I23: #REF! | J23: ='DataBase (IMO form)'!H17 -> M | K23: PASSPORT | L23: ='DataBase (IMO form)'!W17 -> FS151214 | M23: ='DataBase (IMO form)'!Y17 -> 6512 | N23: ='DataBase (IMO form)'!X17 -> 46978
B24: ='DataBase (IMO form)'!B18 -> 11 | C24: ='DataBase (IMO form)'!D18 -> COLEASA | D24: ='DataBase (IMO form)'!E18 -> STEFAN CIPRIAN | E24: ='DataBase (IMO form)'!C18 -> 3RD ENG | F24: ='DataBase (IMO form)'!L18 -> ROMANIAN | G24: ='DataBase (IMO form)'!T18 -> 45912 | H24: ='DataBase (IMO form)'!U18 -> ALTAMIRA, MEXICO | I24: #REF! | J24: ='DataBase (IMO form)'!H18 -> M | K24: PASSPORT | L24: ='DataBase (IMO form)'!W18 -> 063513795 | M24: ='DataBase (IMO form)'!Y18 -> CONSTANTA | N24: ='DataBase (IMO form)'!X18 -> 48638
B25: ='DataBase (IMO form)'!B19 -> 12 | C25: ='DataBase (IMO form)'!D19 -> LOFTSALIS | D25: ='DataBase (IMO form)'!E19 -> APOSTOLOS | E25: ='DataBase (IMO form)'!C19 -> 4TH ENG | F25: ='DataBase (IMO form)'!L19 -> HELLENIC | G25: ='DataBase (IMO form)'!T19 -> 46042 | H25: ='DataBase (IMO form)'!U19 -> GALVESTON, USA | I25: #REF! | J25: ='DataBase (IMO form)'!H19 -> M | K25: PASSPORT | L25: ='DataBase (IMO form)'!W19 -> BB0444273 | M25: ='DataBase (IMO form)'!Y19 -> H.P.H./P.S.D.D. | N25: ='DataBase (IMO form)'!X19 -> 49626
... B42: ='DataBase (IMO form)'!B36 -> 0 | C42: ='DataBase (IMO form)'!D36 -> 0 | D42: ='DataBase (IMO form)'!E36 -> 0 | E42: ='DataBase (IMO form)'!C36 -> 0 | F42: ='DataBase (IMO form)'!L36 -> 0 | G42: ='DataBase (IMO form)'!T36 -> 0 | H42: ='DataBase (IMO form)'!U36 -> 0 | I42: #REF! | J42: ='DataBase (IMO form)'!H36 -> 0 | K42: PASSPORT | L42: ='DataBase (IMO form)'!W36 -> 0 | M42: ='DataBase (IMO form)'!Y36 -> 0 | N42: ='DataBase (IMO form)'!X36 -> 0
B43: ='DataBase (IMO form)'!B36 -> 0 | C43: ='DataBase (IMO form)'!D36 -> 0 | D43: ='DataBase (IMO form)'!E36 -> 0 | E43: ='DataBase (IMO form)'!C36 -> 0 | F43: ='DataBase (IMO form)'!L36 -> 0 | G43: ='DataBase (IMO form)'!T36 -> 0 | H43: ='DataBase (IMO form)'!U36 -> 0 | I43: #REF! | J43: ='DataBase (IMO form)'!H36 -> 0 | K43: PASSPORT | L43: ='DataBase (IMO form)'!W36 -> 0 | M43: ='DataBase (IMO form)'!Y36 -> 0 | N43: ='DataBase (IMO form)'!X36 -> 0
B44: 18. Date and signature by master, authorized agent or officer
C46: =I7 -> 46106
G47: =M.Menu!S16 -> CAPT. WENDT ROBERT
G48: M a s t e r

Sheet Arr Crew List National SB
B2: IMO CREW LIST
B3: IMO FAL FORM 5
L4: Page No.
F5: Arrival Departure | L5: 1/1
B6: 1.1 Name of ship | D6: =M.Menu!E3 -> Energy Endurance | F6: 2. Port of arrival/departure | I6: 3. Date of arrival/departure
B7: 1.2 IMO number | D7: 9859739 | F7: =M.Menu!L11&", "&M.Menu!L12 -> Sabine Pass, U.S.A. | I7: =M.Menu!L13 -> 46106
B8: 1.3 Call sign | D8: =M.Menu!E4 -> V7A7282 | F8: =M.Menu!E8&", "&M.Menu!E9 -> NFE Transport Partners LLC,
B9: 1.4 Voyage number | D9: =M.Menu!S13 -> VOY16
B10: 4. Flag State of ship | F10: 5. Last port of call
B11: =M.Menu!L8 -> Marshall Islands | F11: =M.Menu!E11&", "&M.Menu!E12 -> BARCARENA, BRAZIL
B12: 6. No. | C12: 7. Family name | D12: 8. Given names | E12: 9. Rank or rating | F12: 10. Nationality | G12: 11. Date of birth | H12: 12. Place of birth | J12: 13. Gender | K12: 14. Nature of identity document | L12: 15. Number of identity document | M12: 16. Expiry date of identity document
B14: ='DataBase (IMO form)'!B8 -> 1 | C14: ='DataBase (IMO form)'!D8 -> WENDT | D14: ='DataBase (IMO form)'!E8 -> ROBERT KRZYSZTOF | E14: ='DataBase (IMO form)'!C8 -> MASTER | F14: ='DataBase (IMO form)'!L8 -> POLISH | G14: ='DataBase (IMO form)'!I8 -> 31616 | H14: ='DataBase (IMO form)'!K8 -> GDANSK | I14: #REF! | J14: ='DataBase (IMO form)'!H8 -> M | K14: SEAMAN'S BOOK | L14: ='DataBase (IMO form)'!AD8 -> AA0009998 | M14: ='DataBase (IMO form)'!AE8 -> 48277
B15: ='DataBase (IMO form)'!B9 -> 2 | C15: ='DataBase (IMO form)'!D9 -> THANASIS | D15: ='DataBase (IMO form)'!E9 -> EVANGELOS | E15: ='DataBase (IMO form)'!C9 -> CHIEF OFF | F15: ='DataBase (IMO form)'!L9 -> HELLENIC | G15: ='DataBase (IMO form)'!I9 -> 34373 | H15: ='DataBase (IMO form)'!K9 -> KERKYRA | I15: #REF! | J15: ='DataBase (IMO form)'!H9 -> M | K15: SEAMAN'S BOOK | L15: ='DataBase (IMO form)'!AD9 -> E00363 | M15: ='DataBase (IMO form)'!AE9 -> Lifetime
B16: ='DataBase (IMO form)'!B10 -> 3 | C16: ='DataBase (IMO form)'!D10 -> TEJU | D16: ='DataBase (IMO form)'!E10 -> TOMA | E16: ='DataBase (IMO form)'!C10 -> TR CHIEF OFF | F16: ='DataBase (IMO form)'!L10 -> ROMANIAN | G16: ='DataBase (IMO form)'!I10 -> 32970 | H16: ='DataBase (IMO form)'!K10 -> COSTANTA | I16: #REF! | J16: ='DataBase (IMO form)'!H10 -> M | K16: SEAMAN'S BOOK | L16: ='DataBase (IMO form)'!AD10 -> 86891 | M16: ='DataBase (IMO form)'!AE10 -> Lifetime
B17: ='DataBase (IMO form)'!B11 -> 4 | C17: ='DataBase (IMO form)'!D11 -> BUTS | D17: ='DataBase (IMO form)'!E11 -> KOSTIANTYN | E17: ='DataBase (IMO form)'!C11 -> 2ND OFF | F17: ='DataBase (IMO form)'!L11 -> UKRAINIAN | G17: ='DataBase (IMO form)'!I11 -> 31971 | H17: ='DataBase (IMO form)'!K11 -> UKRAINE | I17: #REF! | J17: ='DataBase (IMO form)'!H11 -> M | K17: SEAMAN'S BOOK | L17: ='DataBase (IMO form)'!AD11 -> 8600199276 | M17: ='DataBase (IMO form)'!AE11 -> 49120
B18: ='DataBase (IMO form)'!B12 -> 5 | C18: ='DataBase (IMO form)'!D12 -> STAMATIOU | D18: ='DataBase (IMO form)'!E12 -> VASILEIOS | E18: ='DataBase (IMO form)'!C12 -> 3RD OFF | F18: ='DataBase (IMO form)'!L12 -> HELLENIC | G18: ='DataBase (IMO form)'!I12 -> 37225 | H18: ='DataBase (IMO form)'!K12 -> MAROUSI | I18: #REF! | J18: ='DataBase (IMO form)'!H12 -> M | K18: SEAMAN'S BOOK | L18: ='DataBase (IMO form)'!AD12 -> AA 61439 | M18: ='DataBase (IMO form)'!AE12 -> Lifetime
B19: ='DataBase (IMO form)'!B13 -> 6 | C19: ='DataBase (IMO form)'!D13 -> KOUIMOV | D19: ='DataBase (IMO form)'!E13 -> ENTOUARNT OR EDUARD | E19: ='DataBase (IMO form)'!C13 -> 3RD OFF | F19: ='DataBase (IMO form)'!L13 -> HELLENIC | G19: ='DataBase (IMO form)'!I13 -> 36547 | H19: ='DataBase (IMO form)'!K13 -> NAKHODKA | I19: #REF! | J19: ='DataBase (IMO form)'!H13 -> M | K19: SEAMAN'S BOOK | L19: ='DataBase (IMO form)'!AD13 -> AA 60496 | M19: ='DataBase (IMO form)'!AE13 -> Lifetime
B20: ='DataBase (IMO form)'!B14 -> 7 | C20: ='DataBase (IMO form)'!D14 -> CHATZIDIMITRIOU | D20: ='DataBase (IMO form)'!E14 -> MARIA | E20: ='DataBase (IMO form)'!C14 -> DECK CADET | F20: ='DataBase (IMO form)'!L14 -> HELLENIC | G20: ='DataBase (IMO form)'!I14 -> 37644 | H20: ='DataBase (IMO form)'!K14 -> THESSALONIKI | I20: #REF! | J20: ='DataBase (IMO form)'!H14 -> F | K20: SEAMAN'S BOOK | L20: ='DataBase (IMO form)'!AD14 -> ST 39373 | M20: ='DataBase (IMO form)'!AE14 -> Lifetime
B21: ='DataBase (IMO form)'!B15 -> 8 | C21: ='DataBase (IMO form)'!D15 -> PETROPOULOS | D21: ='DataBase (IMO form)'!E15 -> CHRISTOS | E21: ='DataBase (IMO form)'!C15 -> CHIEF ENG | F21: ='DataBase (IMO form)'!L15 -> HELLENIC | G21: ='DataBase (IMO form)'!I15 -> 24483 | H21: ='DataBase (IMO form)'!K15 -> KOZANI | I21: #REF! | J21: ='DataBase (IMO form)'!H15 -> M | K21: SEAMAN'S BOOK | L21: ='DataBase (IMO form)'!AD15 -> CY278178 | M21: ='DataBase (IMO form)'!AE15 -> 46683
B22: ='DataBase (IMO form)'!B16 -> 9 | C22: ='DataBase (IMO form)'!D16 -> SYTNYK | D22: ='DataBase (IMO form)'!E16 -> YEVGENIY | E22: ='DataBase (IMO form)'!C16 -> 2ND ENG | F22: ='DataBase (IMO form)'!L16 -> UKRAINIAN | G22: ='DataBase (IMO form)'!I16 -> 32852 | H22: ='DataBase (IMO form)'!K16 -> ODESSA | I22: #REF! | J22: ='DataBase (IMO form)'!H16 -> M | K22: SEAMAN'S BOOK | L22: ='DataBase (IMO form)'!AD16 -> AB 676379 | M22: ='DataBase (IMO form)'!AE16 -> 46128
B23: ='DataBase (IMO form)'!B17 -> 10 | C23: ='DataBase (IMO form)'!D17 -> KACHUR | D23: ='DataBase (IMO form)'!E17 -> MYKOLA | E23: ='DataBase (IMO form)'!C17 -> 3RD ENG | F23: ='DataBase (IMO form)'!L17 -> UKRAINIAN | G23: ='DataBase (IMO form)'!I17 -> 35418 | H23: ='DataBase (IMO form)'!K17 -> UKRAINE | I23: #REF! | J23: ='DataBase (IMO form)'!H17 -> M | K23: SEAMAN'S BOOK | L23: ='DataBase (IMO form)'!AD17 -> AA 1002553 | M23: ='DataBase (IMO form)'!AE17 -> 47308
B24: ='DataBase (IMO form)'!B18 -> 11 | C24: ='DataBase (IMO form)'!D18 -> COLEASA | D24: ='DataBase (IMO form)'!E18 -> STEFAN CIPRIAN | E24: ='DataBase (IMO form)'!C18 -> 3RD ENG | F24: ='DataBase (IMO form)'!L18 -> ROMANIAN | G24: ='DataBase (IMO form)'!I18 -> 33966 | H24: ='DataBase (IMO form)'!K18 -> CONSTANTA | I24: #REF! | J24: ='DataBase (IMO form)'!H18 -> M | K24: SEAMAN'S BOOK | L24: ='DataBase (IMO form)'!AD18 -> 31553CT | M24: ='DataBase (IMO form)'!AE18 -> 46583
B25: ='DataBase (IMO form)'!B19 -> 12 | C25: ='DataBase (IMO form)'!D19 -> LOFTSALIS | D25: ='DataBase (IMO form)'!E19 -> APOSTOLOS | E25: ='DataBase (IMO form)'!C19 -> 4TH ENG | F25: ='DataBase (IMO form)'!L19 -> HELLENIC | G25: ='DataBase (IMO form)'!I19 -> 37555 | H25: ='DataBase (IMO form)'!K19 -> KOZANI | I25: #REF! | J25: ='DataBase (IMO form)'!H19 -> M | K25: SEAMAN'S BOOK | L25: ='DataBase (IMO form)'!AD19 -> ST39185 | M25: ='DataBase (IMO form)'!AE19 -> Lifetime
... B42: ='DataBase (IMO form)'!B36 -> 0 | C42: ='DataBase (IMO form)'!D36 -> 0 | D42: ='DataBase (IMO form)'!E36 -> 0 | E42: ='DataBase (IMO form)'!C36 -> 0 | F42: ='DataBase (IMO form)'!L36 -> 0 | G42: ='DataBase (IMO form)'!I36 -> 0 | H42: ='DataBase (IMO form)'!K36 -> 0 | I42: #REF! | J42: ='DataBase (IMO form)'!H36 -> 0 | K42: SEAMAN'S BOOK | L42: ='DataBase (IMO form)'!AD36 -> 0 | M42: ='DataBase (IMO form)'!AE36 -> 0
B43: 18. Date and signature by master, authorized agent or officer
C45: =I7 -> 46106
G46: =M.Menu!S16 -> CAPT. WENDT ROBERT
G47: M a s t e r

Sheet Arr Crew List Marshall SB
B2: IMO CREW LIST
B3: IMO FAL FORM 5
L4: Page No.
F5: Arrival Departure | L5: 1/1
B6: 1.1 Name of ship | D6: =M.Menu!E3 -> Energy Endurance | F6: 2. Port of arrival/departure | I6: 3. Date of arrival/departure
B7: 1.2 IMO number | D7: 9859739 | F7: =M.Menu!L11&", "&M.Menu!L12 -> Sabine Pass, U.S.A. | I7: =M.Menu!L13 -> 46106
B8: 1.3 Call sign | D8: =M.Menu!E4 -> V7A7282 | F8: =M.Menu!E8&", "&M.Menu!E9 -> NFE Transport Partners LLC,
B9: 1.4 Voyage number | D9: =M.Menu!S13 -> VOY16
B10: 4. Flag State of ship | F10: 5. Last port of call
B11: =M.Menu!L8 -> Marshall Islands | F11: =M.Menu!E11&", "&M.Menu!E12 -> BARCARENA, BRAZIL
B12: 6. No. | C12: 7. Family name | D12: 8. Given names | E12: 9. Rank or rating | F12: 10. Nationality | G12: 11. Date of birth | H12: 12. Place of birth | J12: 13. Gender | K12: 14. Nature of identity document | L12: 15. Number of identity document | M12: 16. Expiry date of identity document
B14: ='DataBase (IMO form)'!B8 -> 1 | C14: ='DataBase (IMO form)'!D8 -> WENDT | D14: ='DataBase (IMO form)'!E8 -> ROBERT KRZYSZTOF | E14: ='DataBase (IMO form)'!C8 -> MASTER | F14: ='DataBase (IMO form)'!L8 -> POLISH | G14: ='DataBase (IMO form)'!I8 -> 31616 | H14: ='DataBase (IMO form)'!K8 -> GDANSK | I14: #REF! | J14: ='DataBase (IMO form)'!H8 -> M | K14: SEAMAN'S BOOK | L14: =IF('DataBase (IMO form)'!AF8=0, 'DataBase (IMO form)'!AH8, 'DataBase (IMO form)'!AF8) -> MH 970901 | M14: ='DataBase (IMO form)'!AG8 -> 46896
B15: ='DataBase (IMO form)'!B9 -> 2 | C15: ='DataBase (IMO form)'!D9 -> THANASIS | D15: ='DataBase (IMO form)'!E9 -> EVANGELOS | E15: ='DataBase (IMO form)'!C9 -> CHIEF OFF | F15: ='DataBase (IMO form)'!L9 -> HELLENIC | G15: ='DataBase (IMO form)'!I9 -> 34373 | H15: ='DataBase (IMO form)'!K9 -> KERKYRA | I15: #REF! | J15: ='DataBase (IMO form)'!H9 -> M | K15: SEAMAN'S BOOK | L15: =IF('DataBase (IMO form)'!AF9=0, 'DataBase (IMO form)'!AH9, 'DataBase (IMO form)'!AF9) -> Original | M15: ='DataBase (IMO form)'!AG9 -> 0
B16: ='DataBase (IMO form)'!B11 -> 4 | C16: ='DataBase (IMO form)'!D11 -> BUTS | D16: ='DataBase (IMO form)'!E11 -> KOSTIANTYN | E16: ='DataBase (IMO form)'!C11 -> 2ND OFF | F16: ='DataBase (IMO form)'!L11 -> UKRAINIAN | G16: ='DataBase (IMO form)'!I11 -> 31971 | H16: ='DataBase (IMO form)'!K11 -> UKRAINE | I16: #REF! | J16: ='DataBase (IMO form)'!H11 -> M | K16: SEAMAN'S BOOK | L16: =IF('DataBase (IMO form)'!AF11=0, 'DataBase (IMO form)'!AH11, 'DataBase (IMO form)'!AF11) -> MH 904486 | M16: ='DataBase (IMO form)'!AG11 -> 46643
B17: ='DataBase (IMO form)'!B12 -> 5 | C17: ='DataBase (IMO form)'!D12 -> STAMATIOU | D17: ='DataBase (IMO form)'!E12 -> VASILEIOS | E17: ='DataBase (IMO form)'!C12 -> 3RD OFF | F17: ='DataBase (IMO form)'!L12 -> HELLENIC | G17: ='DataBase (IMO form)'!I12 -> 37225 | H17: ='DataBase (IMO form)'!K12 -> MAROUSI | I17: #REF! | J17: ='DataBase (IMO form)'!H12 -> M | K17: SEAMAN'S BOOK | L17: =IF('DataBase (IMO form)'!AF12=0, 'DataBase (IMO form)'!AH12, 'DataBase (IMO form)'!AF12) -> MH 956958 | M17: ='DataBase (IMO form)'!AG12 -> 46870
B18: ='DataBase (IMO form)'!B13 -> 6 | C18: ='DataBase (IMO form)'!D13 -> KOUIMOV | D18: ='DataBase (IMO form)'!E13 -> ENTOUARNT OR EDUARD | E18: ='DataBase (IMO form)'!C13 -> 3RD OFF | F18: ='DataBase (IMO form)'!L13 -> HELLENIC | G18: ='DataBase (IMO form)'!I13 -> 36547 | H18: ='DataBase (IMO form)'!K13 -> NAKHODKA | I18: #REF! | J18: ='DataBase (IMO form)'!H13 -> M | K18: SEAMAN'S BOOK | L18: =IF('DataBase (IMO form)'!AF13=0, 'DataBase (IMO form)'!AH13, 'DataBase (IMO form)'!AF13) -> MH 981628 | M18: ='DataBase (IMO form)'!AG13 -> 47003
B19: ='DataBase (IMO form)'!B14 -> 7 | C19: ='DataBase (IMO form)'!D14 -> CHATZIDIMITRIOU | D19: ='DataBase (IMO form)'!E14 -> MARIA | E19: ='DataBase (IMO form)'!C14 -> DECK CADET | F19: ='DataBase (IMO form)'!L14 -> HELLENIC | G19: ='DataBase (IMO form)'!I14 -> 37644 | H19: ='DataBase (IMO form)'!K14 -> THESSALONIKI | I19: #REF! | J19: ='DataBase (IMO form)'!H14 -> F | K19: SEAMAN'S BOOK | L19: =IF('DataBase (IMO form)'!AF14=0, 'DataBase (IMO form)'!AH14, 'DataBase (IMO form)'!AF14) -> MH 1101404 | M19: ='DataBase (IMO form)'!AG14 -> 47560
B20: ='DataBase (IMO form)'!B15 -> 8 | C20: ='DataBase (IMO form)'!D15 -> PETROPOULOS | D20: ='DataBase (IMO form)'!E15 -> CHRISTOS | E20: ='DataBase (IMO form)'!C15 -> CHIEF ENG | F20: ='DataBase (IMO form)'!L15 -> HELLENIC | G20: ='DataBase (IMO form)'!I15 -> 24483 | H20: ='DataBase (IMO form)'!K15 -> KOZANI | I20: #REF! | J20: ='DataBase (IMO form)'!H15 -> M | K20: SEAMAN'S BOOK | L20: =IF('DataBase (IMO form)'!AF15=0, 'DataBase (IMO form)'!AH15, 'DataBase (IMO form)'!AF15) -> MH 859292 | M20: ='DataBase (IMO form)'!AG15 -> 46488
B21: ='DataBase (IMO form)'!B16 -> 9 | C21: ='DataBase (IMO form)'!D16 -> SYTNYK | D21: ='DataBase (IMO form)'!E16 -> YEVGENIY | E21: ='DataBase (IMO form)'!C16 -> 2ND ENG | F21: ='DataBase (IMO form)'!L16 -> UKRAINIAN | G21: ='DataBase (IMO form)'!I16 -> 32852 | H21: ='DataBase (IMO form)'!K16 -> ODESSA | I21: #REF! | J21: ='DataBase (IMO form)'!H16 -> M | K21: SEAMAN'S BOOK | L21: =IF('DataBase (IMO form)'!AF16=0, 'DataBase (IMO form)'!AH16, 'DataBase (IMO form)'!AF16) -> MH 11469449 | M21: ='DataBase (IMO form)'!AG16 -> 47798
B22: ='DataBase (IMO form)'!B17 -> 10 | C22: ='DataBase (IMO form)'!D17 -> KACHUR | D22: ='DataBase (IMO form)'!E17 -> MYKOLA | E22: ='DataBase (IMO form)'!C17 -> 3RD ENG | F22: ='DataBase (IMO form)'!L17 -> UKRAINIAN | G22: ='DataBase (IMO form)'!I17 -> 35418 | H22: ='DataBase (IMO form)'!K17 -> UKRAINE | I22: #REF! | J22: ='DataBase (IMO form)'!H17 -> M | K22: SEAMAN'S BOOK | L22: =IF('DataBase (IMO form)'!AF17=0, 'DataBase (IMO form)'!AH17, 'DataBase (IMO form)'!AF17) -> MH 77412 | M22: ='DataBase (IMO form)'!AG17 -> 46091
B23: ='DataBase (IMO form)'!B18 -> 11 | C23: ='DataBase (IMO form)'!#REF! -> #REF! | D23: ='DataBase (IMO form)'!#REF! -> #REF! | E23: ='DataBase (IMO form)'!C18 -> 3RD ENG | F23: ='DataBase (IMO form)'!#REF! -> #REF! | G23: ='DataBase (IMO form)'!#REF! -> #REF! | H23: ='DataBase (IMO form)'!#REF! -> #REF! | I23: #REF! | J23: ='DataBase (IMO form)'!#REF! -> #REF! | K23: SEAMAN'S BOOK | L23: =IF('DataBase (IMO form)'!#REF!=0, 'DataBase (IMO form)'!#REF!, 'DataBase (IMO form)'!#REF!) -> #REF! | M23: ='DataBase (IMO form)'!#REF! -> #REF!
B24: ='DataBase (IMO form)'!#REF! -> #REF! | C24: ='DataBase (IMO form)'!#REF! -> #REF! | D24: ='DataBase (IMO form)'!#REF! -> #REF! | E24: ='DataBase (IMO form)'!#REF! -> #REF! | F24: ='DataBase (IMO form)'!#REF! -> #REF! | G24: ='DataBase (IMO form)'!#REF! -> #REF! | H24: ='DataBase (IMO form)'!#REF! -> #REF! | I24: #REF! | J24: ='DataBase (IMO form)'!#REF! -> #REF! | K24: SEAMAN'S BOOK | L24: =IF('DataBase (IMO form)'!#REF!=0, 'DataBase (IMO form)'!#REF!, 'DataBase (IMO form)'!#REF!) -> #REF! | M24: ='DataBase (IMO form)'!#REF! -> #REF!
B25: ='DataBase (IMO form)'!B20 -> 13 | C25: ='DataBase (IMO form)'!D20 -> YEMELIANOV | D25: ='DataBase (IMO form)'!E20 -> RICHARD | E25: ='DataBase (IMO form)'!C20 -> GAS ENG | F25: ='DataBase (IMO form)'!L20 -> UKRAINIAN | G25: ='DataBase (IMO form)'!I20 -> 32955 | H25: ='DataBase (IMO form)'!K20 -> UKRAINE | I25: #REF! | J25: ='DataBase (IMO form)'!H20 -> M | K25: SEAMAN'S BOOK | L25: =IF('DataBase (IMO form)'!AF20=0, 'DataBase (IMO form)'!AH20, 'DataBase (IMO form)'!AF20) -> MH 925122 | M25: ='DataBase (IMO form)'!AG20 -> 46741
B26: ='DataBase (IMO form)'!B21 -> 14 | C26: ='DataBase (IMO form)'!D21 -> GIDEI | D26: ='DataBase (IMO form)'!E21 -> NICOLAE | E26: ='DataBase (IMO form)'!C21 -> SETO | F26: ='DataBase (IMO form)'!L21 -> ROMANIAN | G26: ='DataBase (IMO form)'!I21 -> 27720 | H26: ='DataBase (IMO form)'!K21 -> GALATI | I26: #REF! | J26: ='DataBase (IMO form)'!H21 -> M | K26: SEAMAN'S BOOK | L26: =IF('DataBase (IMO form)'!AF21=0, 'DataBase (IMO form)'!AH21, 'DataBase (IMO form)'!AF21) -> MH 916167 | M26: ='DataBase (IMO form)'!AG21 -> 46740
B27: ='DataBase (IMO form)'!#REF! -> #REF! | C27: ='DataBase (IMO form)'!D18 -> COLEASA | D27: ='DataBase (IMO form)'!E18 -> STEFAN CIPRIAN | E27: ='DataBase (IMO form)'!#REF! -> #REF! | F27: ='DataBase (IMO form)'!L18 -> ROMANIAN | G27: ='DataBase (IMO form)'!I18 -> 33966 | H27: ='DataBase (IMO form)'!K18 -> CONSTANTA | I27: #REF! | J27: ='DataBase (IMO form)'!H18 -> M | K27: SEAMAN'S BOOK | L27: =IF('DataBase (IMO form)'!AF18=0, 'DataBase (IMO form)'!AH18, 'DataBase (IMO form)'!AF18) -> Original | M27: ='DataBase (IMO form)'!AG18 -> 0
B28: ='DataBase (IMO form)'!B22 -> 15 | C28: ='DataBase (IMO form)'!D22 -> LADINES | D28: ='DataBase (IMO form)'!E22 -> RODOLFO JR. | E28: ='DataBase (IMO form)'!C22 -> BOSUN | F28: ='DataBase (IMO form)'!L22 -> FILIPINO | G28: ='DataBase (IMO form)'!I22 -> 29241 | H28: ='DataBase (IMO form)'!K22 -> SAMPALOC QUEZON | I28: #REF! | J28: ='DataBase (IMO form)'!H22 -> M | K28: SEAMAN'S BOOK | L28: =IF('DataBase (IMO form)'!AF22=0, 'DataBase (IMO form)'!AH22, 'DataBase (IMO form)'!AF22) -> Original | M28: ='DataBase (IMO form)'!AG22 -> 0
B29: ='DataBase (IMO form)'!B23 -> 16 | C29: ='DataBase (IMO form)'!D23 -> LUPAZ | D29: ='DataBase (IMO form)'!E23 -> ALBERTO JR. | E29: ='DataBase (IMO form)'!C23 -> AB | F29: ='DataBase (IMO form)'!L23 -> FILIPINO | G29: ='DataBase (IMO form)'!I23 -> 34168 | H29: ='DataBase (IMO form)'!K23 -> NASIPIT AND | I29: #REF! | J29: ='DataBase (IMO form)'!H23 -> M | K29: SEAMAN'S BOOK | L29: =IF('DataBase (IMO form)'!AF23=0, 'DataBase (IMO form)'!AH23, 'DataBase (IMO form)'!AF23) -> Original | M29: ='DataBase (IMO form)'!AG23 -> 0
B30: ='DataBase (IMO form)'!B24 -> 17 | C30: ='DataBase (IMO form)'!D24 -> PALERACIO | D30: ='DataBase (IMO form)'!E24 -> JOHN CALLED | E30: ='DataBase (IMO form)'!C24 -> AB | F30: ='DataBase (IMO form)'!L24 -> FILIPINO | G30: ='DataBase (IMO form)'!I24 -> 33759 | H30: ='DataBase (IMO form)'!K24 -> SAMPALOC QUEZON | I30: #REF! | J30: ='DataBase (IMO form)'!H24 -> M | K30: SEAMAN'S BOOK | L30: =IF('DataBase (IMO form)'!AF24=0, 'DataBase (IMO form)'!AH24, 'DataBase (IMO form)'!AF24) -> Original | M30: ='DataBase (IMO form)'!AG24 -> 0
B31: ='DataBase (IMO form)'!B25 -> 18 | C31: ='DataBase (IMO form)'!D25 -> RUFON | D31: ='DataBase (IMO form)'!E25 -> NOEL III | E31: ='DataBase (IMO form)'!C25 -> AB | F31: ='DataBase (IMO form)'!L25 -> FILIPINO | G31: ='DataBase (IMO form)'!I25 -> 35899 | H31: ='DataBase (IMO form)'!K25 -> QUEZON CITY | I31: #REF! | J31: ='DataBase (IMO form)'!H25 -> M | K31: SEAMAN'S BOOK | L31: =IF('DataBase (IMO form)'!AF25=0, 'DataBase (IMO form)'!AH25, 'DataBase (IMO form)'!AF25) -> MH 994967 | M31: ='DataBase (IMO form)'!AG25 -> 47059
B32: ='DataBase (IMO form)'!B27 -> 20 | C32: ='DataBase (IMO form)'!D27 -> ACULIT | D32: ='DataBase (IMO form)'!E27 -> MIKE LISLIE | E32: ='DataBase (IMO form)'!C27 -> OS | F32: ='DataBase (IMO form)'!L27 -> FILIPINO | G32: ='DataBase (IMO form)'!I27 -> 35054 | H32: ='DataBase (IMO form)'!K27 -> BAGO CITY | I32: #REF! | J32: ='DataBase (IMO form)'!H27 -> M | K32: SEAMAN'S BOOK | L32: =IF('DataBase (IMO form)'!AF27=0, 'DataBase (IMO form)'!AH27, 'DataBase (IMO form)'!AF27) -> MH 1065960 | M32: ='DataBase (IMO form)'!AG27 -> 47378
B33: ='DataBase (IMO form)'!B28 -> 21 | C33: ='DataBase (IMO form)'!D28 -> DOMONDON | D33: ='DataBase (IMO form)'!E28 -> DEXTER | E33: ='DataBase (IMO form)'!C28 -> OS | F33: ='DataBase (IMO form)'!L28 -> FILIPINO | G33: ='DataBase (IMO form)'!I28 -> 36084 | H33: ='DataBase (IMO form)'!K28 -> MARIKINA CITY | I33: #REF! | J33: ='DataBase (IMO form)'!H28 -> M | K33: SEAMAN'S BOOK | L33: =IF('DataBase (IMO form)'!AF28=0, 'DataBase (IMO form)'!AH28, 'DataBase (IMO form)'!AF28) -> MH 1159248 | M33: ='DataBase (IMO form)'!AG28 -> 47807
B34: ='DataBase (IMO form)'!B29 -> 22 | C34: ='DataBase (IMO form)'!D29 -> DACANAY | D34: ='DataBase (IMO form)'!E29 -> JAYSON | E34: ='DataBase (IMO form)'!C29 -> FITTER | F34: ='DataBase (IMO form)'!L29 -> FILIPINO | G34: ='DataBase (IMO form)'!I29 -> 33621 | H34: ='DataBase (IMO form)'!K29 -> SISON PANGASINAN | I34: #REF! | J34: ='DataBase (IMO form)'!H29 -> M | K34: SEAMAN'S BOOK | L34: =IF('DataBase (IMO form)'!AF29=0, 'DataBase (IMO form)'!AH29, 'DataBase (IMO form)'!AF29) -> MH 972208 | M34: ='DataBase (IMO form)'!AG29 -> 46947
B35: ='DataBase (IMO form)'!B30 -> 23 | C35: ='DataBase (IMO form)'!D30 -> APID | D35: ='DataBase (IMO form)'!E30 -> LORD BYRON | E35: ='DataBase (IMO form)'!C30 -> MTM | F35: ='DataBase (IMO form)'!L30 -> FILIPINO | G35: 02-May-89 | H35: ='DataBase (IMO form)'!K30 -> DIONISIO ILOILO | I35: #REF! | J35: ='DataBase (IMO form)'!H30 -> M | K35: SEAMAN'S BOOK | L35: =IF('DataBase (IMO form)'!AF30=0, 'DataBase (IMO form)'!AH30, 'DataBase (IMO form)'!AF30) -> MH 995403 | M35: ='DataBase (IMO form)'!AG30 -> 47064
B36: ='DataBase (IMO form)'!B31 -> 24 | C36: ='DataBase (IMO form)'!D31 -> BRILLANTES | D36: ='DataBase (IMO form)'!E31 -> FER ANN | E36: ='DataBase (IMO form)'!C31 -> MTM | F36: ='DataBase (IMO form)'!L31 -> FILIPINO | G36: ='DataBase (IMO form)'!I31 -> 33831 | H36: ='DataBase (IMO form)'!K31 -> ILOILO CITY | I36: #REF! | J36: ='DataBase (IMO form)'!H31 -> M | K36: SEAMAN'S BOOK | L36: =IF('DataBase (IMO form)'!AF31=0, 'DataBase (IMO form)'!AH31, 'DataBase (IMO form)'!AF31) -> MH 879873 | M36: ='DataBase (IMO form)'!AG31 -> 46606
B37: ='DataBase (IMO form)'!B32 -> 25 | C37: ='DataBase (IMO form)'!D32 -> FLORES | D37: ='DataBase (IMO form)'!E32 -> NORIEL | E37: ='DataBase (IMO form)'!C32 -> WIPER | F37: ='DataBase (IMO form)'!L32 -> FILIPINO | G37: ='DataBase (IMO form)'!I32 -> 36550 | H37: ='DataBase (IMO form)'!K32 -> P GALERA OR MDO | I37: #REF! | J37: ='DataBase (IMO form)'!H32 -> M | K37: SEAMAN'S BOOK | L37: =IF('DataBase (IMO form)'!AF32=0, 'DataBase (IMO form)'!AH32, 'DataBase (IMO form)'!AF32) -> MH 1020115 | M37: ='DataBase (IMO form)'!AG32 -> 47180
B38: ='DataBase (IMO form)'!B33 -> 26 | C38: ='DataBase (IMO form)'!D33 -> ESTRABELA | D38: ='DataBase (IMO form)'!E33 -> ARIES | E38: ='DataBase (IMO form)'!C33 -> CHIEF COOK | F38: ='DataBase (IMO form)'!L33 -> FILIPINO | G38: ='DataBase (IMO form)'!I33 -> 34876 | H38: ='DataBase (IMO form)'!K33 -> BARCELONA SSG | I38: #REF! | J38: ='DataBase (IMO form)'!H33 -> M | K38: SEAMAN'S BOOK | L38: =IF('DataBase (IMO form)'!AF33=0, 'DataBase (IMO form)'!AH33, 'DataBase (IMO form)'!AF33) -> MH 972207 | M38: ='DataBase (IMO form)'!AG33 -> 46947
B39: ='DataBase (IMO form)'!B34 -> 27 | C39: ='DataBase (IMO form)'!D34 -> ALLADO | D39: ='DataBase (IMO form)'!E34 -> KEITH VINCENT | E39: ='DataBase (IMO form)'!C34 -> ASS COOK | F39: ='DataBase (IMO form)'!L34 -> FILIPINO | G39: ='DataBase (IMO form)'!I34 -> 34074 | H39: ='DataBase (IMO form)'!K34 -> SAMPALOC QUEZON | I39: #REF! | J39: ='DataBase (IMO form)'!H34 -> M | K39: SEAMAN'S BOOK | L39: =IF('DataBase (IMO form)'!AF34=0, 'DataBase (IMO form)'!AH34, 'DataBase (IMO form)'!AF34) -> Original | M39: ='DataBase (IMO form)'!AG34 -> 0
B40: ='DataBase (IMO form)'!B35 -> 28 | C40: ='DataBase (IMO form)'!D35 -> ABES | D40: ='DataBase (IMO form)'!E35 -> JAMES DARWIN | E40: ='DataBase (IMO form)'!C35 -> MSM | F40: ='DataBase (IMO form)'!L35 -> FILIPINO | G40: ='DataBase (IMO form)'!I35 -> 36409 | H40: ='DataBase (IMO form)'!K35 -> GITAGUM MIS OR | I40: #REF! | J40: ='DataBase (IMO form)'!H35 -> M | K40: SEAMAN'S BOOK | L40: =IF('DataBase (IMO form)'!AF35=0, 'DataBase (IMO form)'!AH35, 'DataBase (IMO form)'!AF35) -> MH 1123766 | M40: ='DataBase (IMO form)'!AG35 -> 47119
B41: ='DataBase (IMO form)'!#REF! -> #REF! | C41: ='DataBase (IMO form)'!#REF! -> #REF! | D41: ='DataBase (IMO form)'!#REF! -> #REF! | E41: ='DataBase (IMO form)'!#REF! -> #REF! | F41: ='DataBase (IMO form)'!#REF! -> #REF! | G41: ='DataBase (IMO form)'!#REF! -> #REF! | H41: ='DataBase (IMO form)'!#REF! -> #REF! | I41: #REF! | J41: ='DataBase (IMO form)'!#REF! -> #REF! | K41: SEAMAN'S BOOK | L41: =IF('DataBase (IMO form)'!#REF!=0, 'DataBase (IMO form)'!#REF!, 'DataBase (IMO form)'!#REF!) -> #REF! | M41: ='DataBase (IMO form)'!#REF! -> #REF!
B42: ='DataBase (IMO form)'!#REF! -> #REF! | C42: ='DataBase (IMO form)'!#REF! -> #REF! | D42: ='DataBase (IMO form)'!#REF! -> #REF! | E42: ='DataBase (IMO form)'!#REF! -> #REF! | F42: ='DataBase (IMO form)'!#REF! -> #REF! | G42: ='DataBase (IMO form)'!#REF! -> #REF! | H42: ='DataBase (IMO form)'!#REF! -> #REF! | I42: #REF! | J42: ='DataBase (IMO form)'!#REF! -> #REF! | K42: SEAMAN'S BOOK | L42: =IF('DataBase (IMO form)'!#REF!=0, 'DataBase (IMO form)'!#REF!, 'DataBase (IMO form)'!#REF!) -> #REF! | M42: ='DataBase (IMO form)'!#REF! -> #REF!
...

Sheet Dep CrewList IMO
B2: IMO CREW LIST
F3: IMO FAL FORM 5
M4: Page No.
G5: Arrival Departure | M5: 1/1
